Workbook

Sheet Mapping
A1: SLFTTP | B1: Orea Transaction.TransactionType | C1: SLFLNT
A2: 01 | B2: "SALE" => "01", if there is no employee discount i.e., When SLFPVC is not EMP | C2: 01 | D2: If Customer ID doesnot exists and if SLFTTP is 01 / Sale | E2: REGULAR SALES
A3: 01 | B3: "SALE" => "01", if there is no employee discount i.e., When SLFPVC is not EMP | C3: 02 | D3: If Customer ID exists and if SLFTTP is 01 / Sale | E3: REGULAR TRADE
A4: 01 | C4: 43 | D4: "AR_PAYMENT" => "43", | E4: AR PAYMENT
A5: 01 | B5: "SALE" => "01", if there is no employee discount i.e., When SLFPVC is not EMP | C5: 45 | D5: If Tenders.Method = "GIFTCARD" | E5: GIFT CARD SALES
A6: 04 | B6: "SALE" => "04", if there is employee discount i.e., When PVCode is EMP | C6: 04 | D6: "SALE" => "04", if there is employee discount i.e., When PVCode is EMP | E6: EMPLOYEE SALES
A7: 11 | B7: "RETURN" => "02", | C7: 11 | D7: If Customer ID doesnot exists and if SLFTTP is 01 / Sale | E7: REGULAR RETURN
A8: 11 | B8: "RETURN" => "02", | C8: 12 | D8: If Customer ID exists and if SLFTTP is 01 / Sale | E8: TRADE RETURN
A9: 11 | B9: "RETURN" => "02", | C9: 45 | D9: If Tenders.Method = "GIFTCARD" | E9: RETURN IN GIFT CARD
A10: 87 | C10: 87 | E10: CURRENT TRANSACTION VOID
A11: 88 | C11: 01 | E11: POST VOID TRANSACTION
A13: TAX
A14: SLFTTP | C14: SLFLNT
A15: 01/02 11/12 | C15: XR | E15: BC PST
C16: XG | E16: GOODS AND SERVICES TAX
C17: XN | E17: HST NEW BRUNSWICK
C18: XF | E18: HST NEWFOUNDLAND
C19: XV | E19: HST NOVA SCOTIA
C20: XH | E20: HST ONTARIO
C21: XI | E21: HST PARTIAL ONTARIO
C22: XP | E22: HST PRINCE EDWARD ISLAND
C23: XM | E23: MANITOBA PST
C24: XQ | E24: QUEBEC Prov Tax
C25: XS | E25: SASK PST
A31: Price Vehicle Code | B31: Price Vehicle Reference
A32: EMP | B32: E99 where 99 is the discount % | C32: employee price
A33: FLR | B33: 6-digits flyer event # | C33: flyer price
A34: MAN | B34: D99 where 99 is the discount % | C34: manual discount
A35: OVD | B35: OVR | C35: override price
A36: PBK | B36: XXX | C36: price book price
A37: REG | B37: ORG | C37: regular retail price
A38: VOL | B38: VOL | C38: volume price
A39: CLR | B39: 6-digits clearance event #

Sheet J26_0539-S
A1: Field | B1: Description | C1: length | D1: SKU2 | F1: SKU line Orea Mapping | G1: SKU Line TTRee Output Logic | K1: Tax Line Orea Mapping | L1: Tax line TTRee logic
A2: SLFTTP | B2: Trans Type | C2: 2 | D2: =_xlfn.XLOOKUP($A2,Sheet3!$P:$P,Sheet3!$Q:$Q) -> 01 | E2: =_xlfn.XLOOKUP($A2,Sheet3!$D:$D,Sheet3!$E:$E) -> 01 | F2: Transaction.transactiontype | G2: Transaction.transactiontype Combined with Mapping Table | I2: =_xlfn.XLOOKUP($A2,Sheet3!$J:$J,Sheet3!$K:$K) -> 01 | K2: Same as SKU | L2: Same as SKU
A3: SLFLNT | B3: Line Type | C3: 2 | D3: =_xlfn.XLOOKUP($A3,Sheet3!$P:$P,Sheet3!$Q:$Q) -> 01 | E3: =_xlfn.XLOOKUP($A3,Sheet3!$D:$D,Sheet3!$E:$E) -> 01 | F3: Transaction.transactiontype | G3: Transaction.transactiontype Combined with Mapping Table | I3: =_xlfn.XLOOKUP($A3,Sheet3!$J:$J,Sheet3!$K:$K) -> XH | K3: N/A | L3: Calculculated based on Requirement mapping table (Tax Authority Sheet) Combination of column D & E = SLFLNT
A4: SLFTDT | B4: Trans Date | C4: 6 | D4: =_xlfn.XLOOKUP($A4,Sheet3!$P:$P,Sheet3!$Q:$Q) -> 260128 | E4: =_xlfn.XLOOKUP($A4,Sheet3!$D:$D,Sheet3!$E:$E) -> 260128 | F4: occurredAt (Provide a list of stores and MMS regions) | G4: Calculated Field based MMS Region occurredAt": "2026-01-13T17:00:53Z", YYMMDD "West - 8 Rest (ON&QC) -5" | I4: =_xlfn.XLOOKUP($A4,Sheet3!$J:$J,Sheet3!$K:$K) -> 260128 | K4: Same as SKU | L4: Same as SKU
A5: SLFTTM | B5: Trans Time | C5: 6 | D5: =_xlfn.XLOOKUP($A5,Sheet3!$P:$P,Sheet3!$Q:$Q) -> 144416 | E5: =_xlfn.XLOOKUP($A5,Sheet3!$D:$D,Sheet3!$E:$E) -> 144416 | F5: occurredAt (Provide a list of stores and MMS regions) | G5: Calculated Field based MMS Region occurredAt": "2026-01-13T17:00:53Z", "West - 8 Rest (ON&QC) -5" | I5: =_xlfn.XLOOKUP($A5,Sheet3!$J:$J,Sheet3!$K:$K) -> 144416 | K5: Same as SKU | L5: Same as SKU
A6: SLFCLK | B6: Store Clerk | C6: 5 | D6: =_xlfn.XLOOKUP($A6,Sheet3!$P:$P,Sheet3!$Q:$Q) -> 00085 | E6: =_xlfn.XLOOKUP($A6,Sheet3!$D:$D,Sheet3!$E:$E) -> 00085 | F6: workstation.registerId | G6: 5-digits number with Preceding zeros eg Register ID = 10 then send "00010" | I6: =_xlfn.XLOOKUP($A6,Sheet3!$J:$J,Sheet3!$K:$K) -> 00085 | K6: Same as SKU | L6: Same as SKU
A7: SLFREG | B7: Register ID | C7: 3 | D7: =_xlfn.XLOOKUP($A7,Sheet3!$P:$P,Sheet3!$Q:$Q) -> 085 | E7: =_xlfn.XLOOKUP($A7,Sheet3!$D:$D,Sheet3!$E:$E) -> 085 | F7: workstation.registerId | G7: 3-digits number with Preceding zeros eg Register ID = 10 then send "010" | I7: =_xlfn.XLOOKUP($A7,Sheet3!$J:$J,Sheet3!$K:$K) -> 085 | K7: Same as SKU | L7: Same as SKU
A8: SLFTTX | B8: Trans Number | C8: 5 | D8: =_xlfn.XLOOKUP($A8,Sheet3!$P:$P,Sheet3!$Q:$Q) -> 00604 | E8: =_xlfn.XLOOKUP($A8,Sheet3!$D:$D,Sheet3!$E:$E) -> 00604 | F8: Logic implemented on Tactill Mapped to: sequenceNumber | G8: Mapping | I8: =_xlfn.XLOOKUP($A8,Sheet3!$J:$J,Sheet3!$K:$K) -> 00604 | K8: Same as SKU | L8: Same as SKU
A9: SLFTSQ | B9: Trans Seq | C9: 5 | D9: =_xlfn.XLOOKUP($A9,Sheet3!$P:$P,Sheet3!$Q:$Q) -> 00002 | E9: =_xlfn.XLOOKUP($A9,Sheet3!$D:$D,Sheet3!$E:$E) -> 00001 | F9: N/A | G9: Implemented in TTRee to represent the line items being sent | I9: =_xlfn.XLOOKUP($A9,Sheet3!$J:$J,Sheet3!$K:$K) -> 00003 | K9: Same as SKU | L9: Same as SKU
A10: SLFSKU | B10: SKU Number | C10: 9 | D10: =_xlfn.XLOOKUP($A10,Sheet3!$P:$P,Sheet3!$Q:$Q) -> 000125728 | E10: =_xlfn.XLOOKUP($A10,Sheet3!$D:$D,Sheet3!$E:$E) -> 000272093 | F10: Item.sku | G10: Mapping | I10: =_xlfn.XLOOKUP($A10,Sheet3!$J:$J,Sheet3!$K:$K) -> 000000000 | K10: N/A | L10: Always 9 Zeros
A11: SLFQTY | B11: Quantity | C11: 9 | D11: =_xlfn.XLOOKUP($A11,Sheet3!$P:$P,Sheet3!$Q:$Q) -> 000000100 | E11: =_xlfn.XLOOKUP($A11,Sheet3!$D:$D,Sheet3!$E:$E) -> 000001200 | F11: Item.Quantity.value | G11: "Total quantity sold per SKU or Total quantity retrun per SKU Mapping it from quantity.value 9 digits with preceding zeros and multiplied by 100 | I11: =_xlfn.XLOOKUP($A11,Sheet3!$J:$J,Sheet3!$K:$K) -> 000000100 | K11: N/A | L11: Always '000000100'
A12: SLFQTN | B12: Negative Sign | C12: 1 | D12: =_xlfn.XLOOKUP($A12,Sheet3!$P:$P,Sheet3!$Q:$Q) | E12: =_xlfn.XLOOKUP($A12,Sheet3!$D:$D,Sheet3!$E:$E) | F12: N/A | G12: Calculated field For Sale always blank Return "-" | I12: =_xlfn.XLOOKUP($A12,Sheet3!$J:$J,Sheet3!$K:$K) | L12: Always Blank
A13: SLFORG | B13: Original Price | C13: 9 | D13: =_xlfn.XLOOKUP($A13,Sheet3!$P:$P,Sheet3!$Q:$Q) -> 000013900 | F13: Item.Pricing.OriginalUnitPrice | G13: 9-digits number with preceding 0s without decimal point Item.Pricing.OriginalUnitPrice | I13: =_xlfn.XLOOKUP($A13,Sheet3!$J:$J,Sheet3!$K:$K) -> 000000000 | L13: Always "000000000"
A14: SLFORN | B14: Negative Sign | C14: 1 | D14: =_xlfn.XLOOKUP($A14,Sheet3!$P:$P,Sheet3!$Q:$Q) | E14: =_xlfn.XLOOKUP($A14,Sheet3!$D:$D,Sheet3!$E:$E) | F14: N/A | G14: always blank | I14: =_xlfn.XLOOKUP($A14,Sheet3!$J:$J,Sheet3!$K:$K) | L14: Same as SKU
A15: SLFADC | B15: Ad Code | C15: 4 | D15: =_xlfn.XLOOKUP($A15,Sheet3!$P:$P,Sheet3!$Q:$Q) -> 0000 | E15: =_xlfn.XLOOKUP($A15,Sheet3!$D:$D,Sheet3!$E:$E) -> 0000 | F15: N/A | G15: #### when the POS price not = regular retail otherwise set to '0000' Calculated field i.e, When Orae PVCode = Reg then 4 Zeros if not send 4 #'s | I15: =_xlfn.XLOOKUP($A15,Sheet3!$J:$J,Sheet3!$K:$K) -> 0000 | L15: Always "0000"
A16: SLFADP | B16: Ad Price | C16: 9 | D16: =_xlfn.XLOOKUP($A16,Sheet3!$P:$P,Sheet3!$Q:$Q) -> 000000000 | E16: =_xlfn.XLOOKUP($A16,Sheet3!$D:$D,Sheet3!$E:$E) -> 000000000 | F16: Item.Pricing.UnitPrice | G16: Calculated Field When PVCode is REG Or MAN then send 9 Zeros If not 9-digits number without decimal point Mapping with Preceding Zeros | I16: =_xlfn.XLOOKUP($A16,Sheet3!$J:$J,Sheet3!$K:$K) -> 000000000 | L16: Always "00000000"
A17: SLFADN | B17: Negative Sign | C17: 1 | D17: =_xlfn.XLOOKUP($A17,Sheet3!$P:$P,Sheet3!$Q:$Q) | E17: =_xlfn.XLOOKUP($A17,Sheet3!$D:$D,Sheet3!$E:$E) | F17: always blank | G17: always blank | I17: =_xlfn.XLOOKUP($A17,Sheet3!$J:$J,Sheet3!$K:$K) | K17: Same as SKU | L17: Same as SKU
A18: SLFOVR | B18: Override Price | C18: 9 | D18: =_xlfn.XLOOKUP($A18,Sheet3!$P:$P,Sheet3!$Q:$Q) -> 000000000 | E18: =_xlfn.XLOOKUP($A18,Sheet3!$D:$D,Sheet3!$E:$E) -> 000000000 | F18: Item.Pricing.priceoverride | G18: Calculated If the override price exists then use Orae Mapping if not send 9 Zeros | I18: =_xlfn.XLOOKUP($A18,Sheet3!$J:$J,Sheet3!$K:$K) -> 000000000 | L18: Always "00000000"
A19: SLFOVN | B19: Negative Sign | C19: 1 | D19: =_xlfn.XLOOKUP($A19,Sheet3!$P:$P,Sheet3!$Q:$Q) | E19: =_xlfn.XLOOKUP($A19,Sheet3!$D:$D,Sheet3!$E:$E) | F19: N/A | G19: always blank | I19: =_xlfn.XLOOKUP($A19,Sheet3!$J:$J,Sheet3!$K:$K) | K19: Same as SKU | L19: Same as SKU
A20: SLFDST | B20: Discount Type | C20: 2 | D20: =_xlfn.XLOOKUP($A20,Sheet3!$P:$P,Sheet3!$Q:$Q) | E20: =_xlfn.XLOOKUP($A20,Sheet3!$D:$D,Sheet3!$E:$E) | F20: N/A | G20: always blank | I20: =_xlfn.XLOOKUP($A20,Sheet3!$J:$J,Sheet3!$K:$K) | L20: Always Blank
A21: SLFDSA | B21: Discount Amount | C21: 9 | D21: =_xlfn.XLOOKUP($A21,Sheet3!$P:$P,Sheet3!$Q:$Q) -> 000000000 | E21: =_xlfn.XLOOKUP($A21,Sheet3!$D:$D,Sheet3!$E:$E) -> 000000000 | F21: N/A | G21: always set to 9 Zeros | I21: =_xlfn.XLOOKUP($A21,Sheet3!$J:$J,Sheet3!$K:$K) -> 000000000 | L21: Always "00000000"
A22: SLFDSN | B22: Negative Sign | C22: 1 | D22: =_xlfn.XLOOKUP($A22,Sheet3!$P:$P,Sheet3!$Q:$Q) | E22: =_xlfn.XLOOKUP($A22,Sheet3!$D:$D,Sheet3!$E:$E) | F22: N/A | G22: always blank | I22: =_xlfn.XLOOKUP($A22,Sheet3!$J:$J,Sheet3!$K:$K) | L22: Same as SKU
A23: SLFSEL | B23: Item Sell Price | C23: 9 | D23: =_xlfn.XLOOKUP($A23,Sheet3!$P:$P,Sheet3!$Q:$Q) -> 000013900 | E23: =_xlfn.XLOOKUP($A23,Sheet3!$D:$D,Sheet3!$E:$E) -> 000000083 | F23: Item.Pricing.Unitprice | G23: Calculated field (Provide Logic) Take the mapping price if override price = zero; otherwise use override price | I23: =_xlfn.XLOOKUP($A23,Sheet3!$J:$J,Sheet3!$K:$K) -> 000001936 | K23: Tax.amount.value | L23: Calculated Total Tax Amount
A24: SLFSLN | B24: Negative Sign | C24: 1 | D24: =_xlfn.XLOOKUP($A24,Sheet3!$P:$P,Sheet3!$Q:$Q) | E24: =_xlfn.XLOOKUP($A24,Sheet3!$D:$D,Sheet3!$E:$E) | F24: N/A | G24: always blank | I24: =_xlfn.XLOOKUP($A24,Sheet3!$J:$J,Sheet3!$K:$K) | K24: Always Blank | L24: Same as SKU
A25: SLFEXT | B25: Extended Value | C25: 11 | D25: =_xlfn.XLOOKUP($A25,Sheet3!$P:$P,Sheet3!$Q:$Q) -> 00000013900 | E25: =_xlfn.XLOOKUP($A25,Sheet3!$D:$D,Sheet3!$E:$E) -> 00000000996 | F25: N/A | G25: Calculated Field Item.quanitity.value * Item.Pricing.UnitPrice If ovreride exists then "Calculated Field Item.quanitity.value * Item.Pricing.PriceOverride | I25: =_xlfn.XLOOKUP($A25,Sheet3!$J:$J,Sheet3!$K:$K) -> 00000001936 | K25: Tax.amount.value | L25: Calculated Total Tax Amount
A26: SLFEXN | B26: Negative Sign | C26: 1 | D26: =_xlfn.XLOOKUP($A26,Sheet3!$P:$P,Sheet3!$Q:$Q) | E26: =_xlfn.XLOOKUP($A26,Sheet3!$D:$D,Sheet3!$E:$E) | F26: N/A | G26: Calculated field "blank means positive set to - for return" | I26: =_xlfn.XLOOKUP($A26,Sheet3!$J:$J,Sheet3!$K:$K) | K26: Calculated field | L26: Same as SKU
A27: SLFTX1 | B27: Charged TAX1 Y/N | C27: 1 | D27: =_xlfn.XLOOKUP($A27,Sheet3!$P:$P,Sheet3!$Q:$Q) -> N | E27: =_xlfn.XLOOKUP($A27,Sheet3!$D:$D,Sheet3!$E:$E) -> N | F27: N/A | G27: Calculated field Default to N Y for SKY with PST charged | I27: =_xlfn.XLOOKUP($A27,Sheet3!$J:$J,Sheet3!$K:$K) -> N | K27: N/A | L27: Always "N"
A28: SLFTX2 | B28: Charged TAX2 Y/N | C28: 1 | D28: =_xlfn.XLOOKUP($A28,Sheet3!$P:$P,Sheet3!$Q:$Q) -> N | E28: =_xlfn.XLOOKUP($A28,Sheet3!$D:$D,Sheet3!$E:$E) -> N | F28: N/A | G28: Calculated field Default to N Y for SKU with GST | I28: =_xlfn.XLOOKUP($A28,Sheet3!$J:$J,Sheet3!$K:$K) -> N | K28: N/A | L28: Always "N"
A29: SLFTX3 | B29: Charged TAX3 Y/N | C29: 1 | D29: =_xlfn.XLOOKUP($A29,Sheet3!$P:$P,Sheet3!$Q:$Q) -> Y | E29: =_xlfn.XLOOKUP($A29,Sheet3!$D:$D,Sheet3!$E:$E) -> Y | F29: N/A | G29: Calculated field Default to N Y for SKU with HST | I29: =_xlfn.XLOOKUP($A29,Sheet3!$J:$J,Sheet3!$K:$K) -> N | K29: N/A | L29: Always "N"
A30: SLFTX4 | B30: Charged TAX4 Y/N | C30: 1 | D30: =_xlfn.XLOOKUP($A30,Sheet3!$P:$P,Sheet3!$Q:$Q) -> N | E30: =_xlfn.XLOOKUP($A30,Sheet3!$D:$D,Sheet3!$E:$E) -> N | F30: N/A | G30: Calculated field Default to N Y for SKU with Partial HST | I30: =_xlfn.XLOOKUP($A30,Sheet3!$J:$J,Sheet3!$K:$K) -> N | K30: N/A | L30: Always "N"
A31: SLFRFC | B31: Reference Code | C31: 1 | D31: =_xlfn.XLOOKUP($A31,Sheet3!$P:$P,Sheet3!$Q:$Q) | E31: =_xlfn.XLOOKUP($A31,Sheet3!$D:$D,Sheet3!$E:$E) | F31: N/A | G31: always blank | I31: =_xlfn.XLOOKUP($A31,Sheet3!$J:$J,Sheet3!$K:$K) | K31: N/A | L31: Same as SKU
A32: SLFRFD | B32: Reference Desc | C32: 16 | D32: =_xlfn.XLOOKUP($A32,Sheet3!$P:$P,Sheet3!$Q:$Q) | E32: =_xlfn.XLOOKUP($A32,Sheet3!$D:$D,Sheet3!$E:$E) | F32: N/A | G32: always blank | I32: =_xlfn.XLOOKUP($A32,Sheet3!$J:$J,Sheet3!$K:$K) | K32: N/A | L32: Same as SKU
A33: SLFUPC | B33: UPC Code | C33: 13 | D33: =_xlfn.XLOOKUP($A33,Sheet3!$P:$P,Sheet3!$Q:$Q) -> 0000000000000 | E33: =_xlfn.XLOOKUP($A33,Sheet3!$D:$D,Sheet3!$E:$E) -> 0000000000000 | F33: item.gtin | G33: item.gtin If no value, set it to 13 Zeros | I33: =_xlfn.XLOOKUP($A33,Sheet3!$J:$J,Sheet3!$K:$K) -> 0000000000000 | K33: N/A | L33: Always 13 Zeros
A34: SLFSPS | B34: Sales Person | C34: 5 | D34: =_xlfn.XLOOKUP($A34,Sheet3!$P:$P,Sheet3!$Q:$Q) -> 00085 | E34: =_xlfn.XLOOKUP($A34,Sheet3!$D:$D,Sheet3!$E:$E) -> 00085 | F34: SCO - Workstation.RegisterID ACO- actor.cashier.loginid | G34: Calculated If register Starts with 8 then SCO if not its ACO SCO = use register ID ampping - prefix Zeros upto 5 digits ACO = Mapping default 5 0s | I34: =_xlfn.XLOOKUP($A34,Sheet3!$J:$J,Sheet3!$K:$K) -> 00085 | K34: Same as SKU | L34: Same as SKU
A35: SLFSTS | B35: Status | C35: 1 | D35: =_xlfn.XLOOKUP($A35,Sheet3!$P:$P,Sheet3!$Q:$Q) | E35: =_xlfn.XLOOKUP($A35,Sheet3!$D:$D,Sheet3!$E:$E) | F35: N/A | G35: always blank | I35: =_xlfn.XLOOKUP($A35,Sheet3!$J:$J,Sheet3!$K:$K) | K35: N/A | L35: Same as SKU
A36: 2 | B36: Zip Code | C36: 10 | D36: =_xlfn.XLOOKUP($A36,Sheet3!$P:$P,Sheet3!$Q:$Q) -> #N/A | E36: =_xlfn.XLOOKUP($A36,Sheet3!$D:$D,Sheet3!$E:$E) -> #N/A | F36: transaction.items[i].attributes["x-epp-coverage-identifier"] | G36: Mappiing | H36: High | I36: =_xlfn.XLOOKUP($A36,Sheet3!$J:$J,Sheet3!$K:$K) -> #N/A | K36: N/A | L36: Always 10 Zeros 9 spaced + 0 i.e, " 0"
A37: SLFCNM | B37: Customer Name | C37: 35 | D37: =_xlfn.XLOOKUP($A37,Sheet3!$P:$P,Sheet3!$Q:$Q) | E37: =_xlfn.XLOOKUP($A37,Sheet3!$D:$D,Sheet3!$E:$E) | F37: N/A | G37: always blank | I37: =_xlfn.XLOOKUP($A37,Sheet3!$J:$J,Sheet3!$K:$K) | K37: N/A | L37: Always Blank
A38: SLFNUM | B38: Customer Number | C38: 10 | D38: =_xlfn.XLOOKUP($A38,Sheet3!$P:$P,Sheet3!$Q:$Q) | E38: =_xlfn.XLOOKUP($A38,Sheet3!$D:$D,Sheet3!$E:$E) | F38: Customer.customerIdToken | G38: Mapping default to blank | I38: =_xlfn.XLOOKUP($A38,Sheet3!$J:$J,Sheet3!$K:$K) | K38: Same as SKU | L38: Same as SKU
A39: SLFRSN | B39: Reason Code | C39: 16 | D39: =_xlfn.XLOOKUP($A39,Sheet3!$P:$P,Sheet3!$Q:$Q) | E39: =_xlfn.XLOOKUP($A39,Sheet3!$D:$D,Sheet3!$E:$E) | F39: ??? | G39: return reason code (RRT0) + Mapping price override reason code (POV0) + Mapping post voided reason code (VOD0) left justified" Default to Blank | I39: =_xlfn.XLOOKUP($A39,Sheet3!$J:$J,Sheet3!$K:$K) | K39: N/A | L39: Always Blank
A40: SLFOSP | B40: Original Salesperson | C40: 5 | D40: =_xlfn.XLOOKUP($A40,Sheet3!$P:$P,Sheet3!$Q:$Q) -> 00000 | E40: =_xlfn.XLOOKUP($A40,Sheet3!$D:$D,Sheet3!$E:$E) -> 00000 | F40: N/A | G40: always 5 zeros | I40: =_xlfn.XLOOKUP($A40,Sheet3!$J:$J,Sheet3!$K:$K) -> 00000 | K40: N/A | L40: Same as SKU
...

Sheet J26_0539-T
F1: jan 22 | H1: PPR Jan 23 - Multi Products | J1: Jan 26 Multiple SKU
A2: Field | B2: Description | C2: length | D2: Priority | F2: TTress | G2: Fixes Needed | H2: TTress | I2: Fixes Needed | K2: Tender line Orea Mapping | L2: Tender Line TTRee Logic
A3: TNFTTP | B3: Transaction Type | C3: 2 | E3: =_xlfn.XLOOKUP($A3,Sheet3!$V:$V,Sheet3!$W:$W) -> 01 | F3: 01 | H3: =_xlfn.IFNA(_xlfn.XLOOKUP($A3,'T-00531'!$D:$D,'T-00531'!$E:$E),"Not in Sheet1") -> 01 | J3: =_xlfn.XLOOKUP($A2,Sheet3!$P:$P,Sheet3!$Q:$Q) -> #N/A | K3: Same as SLFTTP | L3: Same as SLFTTP
A4: TNFTDT | B4: Transaction Date | C4: 6 | E4: =_xlfn.XLOOKUP($A4,Sheet3!$V:$V,Sheet3!$W:$W) -> 260128 | F4: 260122 | H4: =_xlfn.IFNA(_xlfn.XLOOKUP($A4,'T-00531'!$D:$D,'T-00531'!$E:$E),"Not in Sheet1") -> 260123 | J4: =_xlfn.XLOOKUP($A4,Sheet3!$P:$P,Sheet3!$Q:$Q) -> #N/A | K4: occurredAt (Provide a list of stores and MMS regions) | L4: Calculated Field based MMS Region occurredAt": "2026-01-13T17:00:53Z", YYMMDD "West - 8 Rest (ON&QC) -5"
A5: TNFTTM | B5: Transaction Time | C5: 6 | D5: Critical | E5: =_xlfn.XLOOKUP($A5,Sheet3!$V:$V,Sheet3!$W:$W) -> 144416 | F5: 125002 | G5: 075002 | H5: =_xlfn.IFNA(_xlfn.XLOOKUP($A5,'T-00531'!$D:$D,'T-00531'!$E:$E),"Not in Sheet1") -> 154417 | J5: =_xlfn.XLOOKUP($A5,Sheet3!$P:$P,Sheet3!$Q:$Q) -> #N/A | K5: occurredAt (Provide a list of stores and MMS regions) | L5: Calculated Field based MMS Region occurredAt": "2026-01-13T17:00:53Z", HHMMSS "West - 8 Rest (ON&QC) -5"
A6: TNFCLK | B6: Clerk | C6: 5 | E6: =_xlfn.XLOOKUP($A6,Sheet3!$V:$V,Sheet3!$W:$W) -> 00085 | F6: 00081 | H6: =_xlfn.IFNA(_xlfn.XLOOKUP($A6,'T-00531'!$D:$D,'T-00531'!$E:$E),"Not in Sheet1") -> 00085 | J6: =_xlfn.XLOOKUP($A6,Sheet3!$P:$P,Sheet3!$Q:$Q) -> #N/A | K6: workstation.registerId | L6: 5-digits number with Preceding zeros eg Register ID = 10 then send "00010"
A7: TNFREG | B7: Register ID | C7: 3 | E7: =_xlfn.XLOOKUP($A7,Sheet3!$V:$V,Sheet3!$W:$W) -> 085 | F7: 081 | H7: =_xlfn.IFNA(_xlfn.XLOOKUP($A7,'T-00531'!$D:$D,'T-00531'!$E:$E),"Not in Sheet1") -> 085 | J7: =_xlfn.XLOOKUP($A7,Sheet3!$P:$P,Sheet3!$Q:$Q) -> #N/A | K7: workstation.registerId | L7: 3-digits number with Preceding zeros eg Register ID = 10 then send "010"
A8: TNFTTX | B8: Transaction Number | C8: 5 | E8: =_xlfn.XLOOKUP($A8,Sheet3!$V:$V,Sheet3!$W:$W) -> 00604 | F8: 00129 | H8: =_xlfn.IFNA(_xlfn.XLOOKUP($A8,'T-00531'!$D:$D,'T-00531'!$E:$E),"Not in Sheet1") -> 00531 | J8: =_xlfn.XLOOKUP($A8,Sheet3!$P:$P,Sheet3!$Q:$Q) -> #N/A | K8: Logic implemented on Tactill Mapped to: sequenceNumber | L8: Mapping
A9: TNFTSQ | B9: Transaction Seq | C9: 5 | E9: =_xlfn.XLOOKUP($A9,Sheet3!$V:$V,Sheet3!$W:$W) -> 00004 | F9: 00003 | H9: =_xlfn.IFNA(_xlfn.XLOOKUP($A9,'T-00531'!$D:$D,'T-00531'!$E:$E),"Not in Sheet1") -> 00005 | J9: =_xlfn.XLOOKUP($A9,Sheet3!$P:$P,Sheet3!$Q:$Q) -> #N/A | K9: N/A | L9: Implemented in TTRee to represent the line items being sent
A10: TNFFCD | B10: Fund Code | C10: 2 | E10: =_xlfn.XLOOKUP($A10,Sheet3!$V:$V,Sheet3!$W:$W) -> VI | F10: VI | H10: =_xlfn.IFNA(_xlfn.XLOOKUP($A10,'T-00531'!$D:$D,'T-00531'!$E:$E),"Not in Sheet1") -> VI | J10: =_xlfn.XLOOKUP($A10,Sheet3!$P:$P,Sheet3!$Q:$Q) -> #N/A | K10: tenders.card.scheme | L10: Mapping combined with fundcode table
A11: TNFAMT | B11: Amount | C11: 11 | E11: =_xlfn.XLOOKUP($A11,Sheet3!$V:$V,Sheet3!$W:$W) -> 00000016832 | F11: 00000000506 | H11: =_xlfn.IFNA(_xlfn.XLOOKUP($A11,'T-00531'!$D:$D,'T-00531'!$E:$E),"Not in Sheet1") -> 00000002586 | J11: =_xlfn.XLOOKUP($A11,Sheet3!$P:$P,Sheet3!$Q:$Q) -> #N/A | K11: tender.amount.value | L11: Mapping
A12: TNFAMN | B12: Negative Sign | C12: 1 | E12: =_xlfn.XLOOKUP($A12,Sheet3!$V:$V,Sheet3!$W:$W) | F12: Blank | H12: =_xlfn.IFNA(_xlfn.XLOOKUP($A12,'T-00531'!$D:$D,'T-00531'!$E:$E),"Not in Sheet1") | J12: =_xlfn.XLOOKUP($A12,Sheet3!$P:$P,Sheet3!$Q:$Q) -> #N/A | K12: N/A | L12: Calculated Sales = Always Blank Returns = "-"
A13: TNFCCD | B13: Credit Card | C13: 19 | D13: Critical | E13: =_xlfn.XLOOKUP($A13,Sheet3!$V:$V,Sheet3!$W:$W) -> ***************4902 | F13: VISA3332 | G13: ************3332 | H13: =_xlfn.IFNA(_xlfn.XLOOKUP($A13,'T-00531'!$D:$D,'T-00531'!$E:$E),"Not in Sheet1") -> ***************4903 | J13: =_xlfn.XLOOKUP($A13,Sheet3!$P:$P,Sheet3!$Q:$Q) -> #N/A | K13: tenders.card.last 4 | L13: Calculated need to apply prefix of 12 *s to Mapping
A14: TNFEXP | B14: Card Exp. Date | C14: 4 | E14: =_xlfn.XLOOKUP($A14,Sheet3!$V:$V,Sheet3!$W:$W) -> 0000 | F14: 0000 | H14: =_xlfn.IFNA(_xlfn.XLOOKUP($A14,'T-00531'!$D:$D,'T-00531'!$E:$E),"Not in Sheet1") -> 0000 | J14: =_xlfn.XLOOKUP($A14,Sheet3!$P:$P,Sheet3!$Q:$Q) -> #N/A | K14: N/A | L14: Always 4 Zeros
A15: TNFAUT | B15: Auth Number | C15: 6 | E15: =_xlfn.XLOOKUP($A15,Sheet3!$V:$V,Sheet3!$W:$W) -> 066851 | F15: 055794 | H15: =_xlfn.IFNA(_xlfn.XLOOKUP($A15,'T-00531'!$D:$D,'T-00531'!$E:$E),"Not in Sheet1") -> 066851 | J15: =_xlfn.XLOOKUP($A15,Sheet3!$P:$P,Sheet3!$Q:$Q) -> #N/A | K15: Tenders.Card.AuthCode | L15: Mapping For Flexity - Send only last 6 digits
A16: TNFRFC | B16: Reference Code | C16: 1 | D16: Critical | E16: =_xlfn.XLOOKUP($A16,Sheet3!$V:$V,Sheet3!$W:$W) | F16: T | G16: Blank | H16: =_xlfn.IFNA(_xlfn.XLOOKUP($A16,'T-00531'!$D:$D,'T-00531'!$E:$E),"Not in Sheet1") | J16: =_xlfn.XLOOKUP($A16,Sheet3!$P:$P,Sheet3!$Q:$Q) -> #N/A | K16: N/A | L16: Always blank
A17: TNFRDS | B17: Reference Desc | C17: 16 | D17: Critical | E17: =_xlfn.XLOOKUP($A17,Sheet3!$V:$V,Sheet3!$W:$W) | F17: CREDIT | G17: Blank | H17: =_xlfn.IFNA(_xlfn.XLOOKUP($A17,'T-00531'!$D:$D,'T-00531'!$E:$E),"Not in Sheet1") | J17: =_xlfn.XLOOKUP($A17,Sheet3!$P:$P,Sheet3!$Q:$Q) -> #N/A | L17: Always Blank for Debit,credit and Flexiti and gift card Redemption
A18: TNFMBR | B18: Customer/Mbr | C18: 8 | D18: High | E18: =_xlfn.XLOOKUP($A18,Sheet3!$V:$V,Sheet3!$W:$W) | F18: Blank | G18: 00000000 | H18: =_xlfn.IFNA(_xlfn.XLOOKUP($A18,'T-00531'!$D:$D,'T-00531'!$E:$E),"Not in Sheet1") | J18: =_xlfn.XLOOKUP($A18,Sheet3!$P:$P,Sheet3!$Q:$Q) -> #N/A | K18: N/A | L18: Always blank
A19: TNFSTS | B19: Status - A=ACTIVE; D=DELE | C19: 1 | E19: =_xlfn.XLOOKUP($A19,Sheet3!$V:$V,Sheet3!$W:$W) | F19: Blank | H19: =_xlfn.IFNA(_xlfn.XLOOKUP($A19,'T-00531'!$D:$D,'T-00531'!$E:$E),"Not in Sheet1") | J19: =_xlfn.XLOOKUP($A19,Sheet3!$P:$P,Sheet3!$Q:$Q) -> #N/A | K19: N/A | L19: Always blank
A20: TNFESI | B20: Employee Sale ID | C20: 5 | E20: =_xlfn.XLOOKUP($A20,Sheet3!$V:$V,Sheet3!$W:$W) | F20: Blank | H20: =_xlfn.IFNA(_xlfn.XLOOKUP($A20,'T-00531'!$D:$D,'T-00531'!$E:$E),"Not in Sheet1") | J20: =_xlfn.XLOOKUP($A20,Sheet3!$P:$P,Sheet3!$Q:$Q) -> #N/A | K20: N/A | L20: Calculated field set to '#####' for all employee sale i.e.TNFTTP = '04' Default to Blank
A21: TNFZIP | B21: Postal Code | C21: 10 | E21: =_xlfn.XLOOKUP($A21,Sheet3!$V:$V,Sheet3!$W:$W) | F21: Blank | H21: =_xlfn.IFNA(_xlfn.XLOOKUP($A21,'T-00531'!$D:$D,'T-00531'!$E:$E),"Not in Sheet1") | J21: =_xlfn.XLOOKUP($A21,Sheet3!$P:$P,Sheet3!$Q:$Q) -> #N/A | K21: N/A | L21: Always blank
A22: TNFMSR | B22: Mag Stripe Flag | C22: 1 | D22: Critical | E22: =_xlfn.XLOOKUP($A22,Sheet3!$V:$V,Sheet3!$W:$W) -> S | F22: Blank | G22: t | H22: =_xlfn.IFNA(_xlfn.XLOOKUP($A22,'T-00531'!$D:$D,'T-00531'!$E:$E),"Not in Sheet1") -> S | J22: =_xlfn.XLOOKUP($A22,Sheet3!$P:$P,Sheet3!$Q:$Q) -> #N/A | K22: ORAE.Transaction.Tenders[n].card.emv.tags.magStrip | L22: Mapping
A23: TNFEML | B23: eReceipt email | C23: 60 | E23: =_xlfn.XLOOKUP($A23,Sheet3!$V:$V,Sheet3!$W:$W) | F23: Blank | H23: =_xlfn.IFNA(_xlfn.XLOOKUP($A23,'T-00531'!$D:$D,'T-00531'!$E:$E),"Not in Sheet1") | J23: =_xlfn.XLOOKUP($A23,Sheet3!$P:$P,Sheet3!$Q:$Q) -> #N/A | L23: Always blank
A24: TNFHSH | B24: Payment Hash Value | C24: 64 | E24: =_xlfn.XLOOKUP($A24,Sheet3!$V:$V,Sheet3!$W:$W) | F24: Blank | H24: =_xlfn.IFNA(_xlfn.XLOOKUP($A24,'T-00531'!$D:$D,'T-00531'!$E:$E),"Not in Sheet1") | J24: =_xlfn.XLOOKUP($A24,Sheet3!$P:$P,Sheet3!$Q:$Q) -> #N/A | K24: N/A | L24: Always blank
A25: TNFPLC | B25: Polled Store | C25: 5 | E25: =_xlfn.XLOOKUP($A25,Sheet3!$V:$V,Sheet3!$W:$W) -> 55010 | F25: 83010 | H25: =_xlfn.IFNA(_xlfn.XLOOKUP($A25,'T-00531'!$D:$D,'T-00531'!$E:$E),"Not in Sheet1") -> 55010 | J25: =_xlfn.XLOOKUP($A25,Sheet3!$P:$P,Sheet3!$Q:$Q) -> #N/A | K25: BusinessContext.Store.StoreID | L25: Mapping
A26: TNFPCN | B26: Poll Cen | C26: 1 | E26: =_xlfn.XLOOKUP($A26,Sheet3!$V:$V,Sheet3!$W:$W) -> 1 | F26: 1 | H26: =_xlfn.IFNA(_xlfn.XLOOKUP($A26,'T-00531'!$D:$D,'T-00531'!$E:$E),"Not in Sheet1") -> 1 | J26: =_xlfn.XLOOKUP($A26,Sheet3!$P:$P,Sheet3!$Q:$Q) -> #N/A | K26: N/A | L26: 1
A27: TNFPDT | B27: Poll Date | C27: 6 | E27: =_xlfn.XLOOKUP($A27,Sheet3!$V:$V,Sheet3!$W:$W) -> 260128 | F27: 260122 | H27: =_xlfn.IFNA(_xlfn.XLOOKUP($A27,'T-00531'!$D:$D,'T-00531'!$E:$E),"Not in Sheet1") -> 260123 | J27: =_xlfn.XLOOKUP($A27,Sheet3!$P:$P,Sheet3!$Q:$Q) -> #N/A | K27: occurredAt (Provide a list of stores and MMS regions) | L27: Calculated Field based MMS Region occurredAt": "2026-01-13T17:00:53Z", YYMMDD "West - 8 Rest (ON&QC) -5"
A28: TNFCCN | B28: Create Cen | C28: 1 | E28: =_xlfn.XLOOKUP($A28,Sheet3!$V:$V,Sheet3!$W:$W) -> 1 | F28: 1 | H28: =_xlfn.IFNA(_xlfn.XLOOKUP($A28,'T-00531'!$D:$D,'T-00531'!$E:$E),"Not in Sheet1") -> 1 | J28: =_xlfn.XLOOKUP($A28,Sheet3!$P:$P,Sheet3!$Q:$Q) -> #N/A | K28: N/A | L28: 1
A29: TNFCDT | B29: Create Date | C29: 6 | E29: =_xlfn.XLOOKUP($A29,Sheet3!$V:$V,Sheet3!$W:$W) -> 260128 | F29: 260122 | H29: =_xlfn.IFNA(_xlfn.XLOOKUP($A29,'T-00531'!$D:$D,'T-00531'!$E:$E),"Not in Sheet1") -> 260123 | J29: =_xlfn.XLOOKUP($A29,Sheet3!$P:$P,Sheet3!$Q:$Q) -> #N/A | K29: occurredAt (Provide a list of stores and MMS regions) | L29: Calculated Field based MMS Region occurredAt": "2026-01-13T17:00:53Z", YYMMDD "West - 8 Rest (ON&QC) -5"
A30: TNFCTM | B30: Create Time | C30: 6 | E30: =_xlfn.XLOOKUP($A30,Sheet3!$V:$V,Sheet3!$W:$W) -> 144416 | F30: 75002 | H30: =_xlfn.IFNA(_xlfn.XLOOKUP($A30,'T-00531'!$D:$D,'T-00531'!$E:$E),"Not in Sheet1") -> 154417 | J30: =_xlfn.XLOOKUP($A30,Sheet3!$P:$P,Sheet3!$Q:$Q) -> #N/A | K30: occurredAt (Provide a list of stores and MMS regions) | L30: Calculated Field based MMS Region occurredAt": "2026-01-13T17:00:53Z", "West - 8 Rest (ON&QC) -5" HHMMSS
A31: ATFSST | B31: Sales Store | C31: 5 | E31: =_xlfn.XLOOKUP($A31,Sheet3!$V:$V,Sheet3!$W:$W) -> 0 | F31: 0 | H31: =_xlfn.IFNA(_xlfn.XLOOKUP($A31,'T-00531'!$D:$D,'T-00531'!$E:$E),"Not in Sheet1") -> 0 | J31: =_xlfn.XLOOKUP($A31,Sheet3!$P:$P,Sheet3!$Q:$Q) -> #N/A | K31: N/A | L31: always 0
A32: ATFIST | B32: Inv. Store | C32: 5 | E32: =_xlfn.XLOOKUP($A32,Sheet3!$V:$V,Sheet3!$W:$W) -> 0 | F32: 0 | H32: =_xlfn.IFNA(_xlfn.XLOOKUP($A32,'T-00531'!$D:$D,'T-00531'!$E:$E),"Not in Sheet1") -> 0 | J32: =_xlfn.XLOOKUP($A32,Sheet3!$P:$P,Sheet3!$Q:$Q) -> #N/A | K32: N/A | L32: always 0
A33: ATFOTX | B33: Original Trans# | C33: 5 | E33: =_xlfn.XLOOKUP($A33,Sheet3!$V:$V,Sheet3!$W:$W) | F33: Blank | H33: =_xlfn.IFNA(_xlfn.XLOOKUP($A33,'T-00531'!$D:$D,'T-00531'!$E:$E),"Not in Sheet1") | J33: =_xlfn.XLOOKUP($A33,Sheet3!$P:$P,Sheet3!$Q:$Q) -> #N/A | K33: N/A | L33: always blank
A34: ATFMBT | B34: Customer Type | C34: 1 | E34: =_xlfn.XLOOKUP($A34,Sheet3!$V:$V,Sheet3!$W:$W) | F34: Blank | H34: =_xlfn.IFNA(_xlfn.XLOOKUP($A34,'T-00531'!$D:$D,'T-00531'!$E:$E),"Not in Sheet1") | J34: =_xlfn.XLOOKUP($A34,Sheet3!$P:$P,Sheet3!$Q:$Q) -> #N/A | K34: N/A | L34: always blank
A35: ATFORD | B35: Order Number | C35: 8 | E35: =_xlfn.XLOOKUP($A35,Sheet3!$V:$V,Sheet3!$W:$W) | F35: Blank | H35: =_xlfn.IFNA(_xlfn.XLOOKUP($A35,'T-00531'!$D:$D,'T-00531'!$E:$E),"Not in Sheet1") | J35: =_xlfn.XLOOKUP($A35,Sheet3!$P:$P,Sheet3!$Q:$Q) -> #N/A | K35: N/A | L35: always blank
A36: ATFPRO | B36: Project Number | C36: 5 | E36: =_xlfn.XLOOKUP($A36,Sheet3!$V:$V,Sheet3!$W:$W) | F36: Blank | H36: =_xlfn.IFNA(_xlfn.XLOOKUP($A36,'T-00531'!$D:$D,'T-00531'!$E:$E),"Not in Sheet1") | J36: =_xlfn.XLOOKUP($A36,Sheet3!$P:$P,Sheet3!$Q:$Q) -> #N/A | K36: N/A | L36: always blank
J37: =_xlfn.XLOOKUP($A37,Sheet3!$P:$P,Sheet3!$Q:$Q) -> 0

Sheet T-00531
A2: TNFTTP: "01", | B2: =SUBSTITUTE(SUBSTITUTE(A2,"""",""),",","") -> TNFTTP: 01 | C2: =_xlfn.TEXTBEFORE(B2,":") -> TNFTTP | D2: =SUBSTITUTE(TRIM(C2)," ","") -> TNFTTP | E2: =_xlfn.TEXTAFTER(B2,":") -> 01 | G2: =COUNTIF('T-00531'!D:D,A2) -> 0
A3: "TNFTDT": "260123", | B3: =SUBSTITUTE(SUBSTITUTE(A3,"""",""),",","") -> TNFTDT: 260123 | C3: =_xlfn.TEXTBEFORE(B3,":") -> TNFTDT | D3: =SUBSTITUTE(TRIM(C3)," ","") -> TNFTDT | E3: =_xlfn.TEXTAFTER(B3,":") -> 260123 | G3: =COUNTIF('T-00531'!D:D,A3) -> 0
A4: "TNFTTM": "154417", | B4: =SUBSTITUTE(SUBSTITUTE(A4,"""",""),",","") -> TNFTTM: 154417 | C4: =_xlfn.TEXTBEFORE(B4,":") -> TNFTTM | D4: =SUBSTITUTE(TRIM(C4)," ","") -> TNFTTM | E4: =_xlfn.TEXTAFTER(B4,":") -> 154417 | G4: =COUNTIF('T-00531'!D:D,A4) -> 0
A5: "TNFCLK": "00085", | B5: =SUBSTITUTE(SUBSTITUTE(A5,"""",""),",","") -> TNFCLK: 00085 | C5: =_xlfn.TEXTBEFORE(B5,":") -> TNFCLK | D5: =SUBSTITUTE(TRIM(C5)," ","") -> TNFCLK | E5: =_xlfn.TEXTAFTER(B5,":") -> 00085 | G5: =COUNTIF('T-00531'!D:D,A5) -> 0
A6: "TNFREG": "085", | B6: =SUBSTITUTE(SUBSTITUTE(A6,"""",""),",","") -> TNFREG: 085 | C6: =_xlfn.TEXTBEFORE(B6,":") -> TNFREG | D6: =SUBSTITUTE(TRIM(C6)," ","") -> TNFREG | E6: =_xlfn.TEXTAFTER(B6,":") -> 085 | G6: =COUNTIF('T-00531'!D:D,A6) -> 0
A7: "TNFTTX": "00531", | B7: =SUBSTITUTE(SUBSTITUTE(A7,"""",""),",","") -> TNFTTX: 00531 | C7: =_xlfn.TEXTBEFORE(B7,":") -> TNFTTX | D7: =SUBSTITUTE(TRIM(C7)," ","") -> TNFTTX | E7: =_xlfn.TEXTAFTER(B7,":") -> 00531 | G7: =COUNTIF('T-00531'!D:D,A7) -> 0
A8: "TNFTSQ": "00005", | B8: =SUBSTITUTE(SUBSTITUTE(A8,"""",""),",","") -> TNFTSQ: 00005 | C8: =_xlfn.TEXTBEFORE(B8,":") -> TNFTSQ | D8: =SUBSTITUTE(TRIM(C8)," ","") -> TNFTSQ | E8: =_xlfn.TEXTAFTER(B8,":") -> 00005 | G8: =COUNTIF('T-00531'!D:D,A8) -> 0
A9: "TNFFCD": "VI", | B9: =SUBSTITUTE(SUBSTITUTE(A9,"""",""),",","") -> TNFFCD: VI | C9: =_xlfn.TEXTBEFORE(B9,":") -> TNFFCD | D9: =SUBSTITUTE(TRIM(C9)," ","") -> TNFFCD | E9: =_xlfn.TEXTAFTER(B9,":") -> VI
A10: "TNFAMT": "00000002586", | B10: =SUBSTITUTE(SUBSTITUTE(A10,"""",""),",","") -> TNFAMT: 00000002586 | C10: =_xlfn.TEXTBEFORE(B10,":") -> TNFAMT | D10: =SUBSTITUTE(TRIM(C10)," ","") -> TNFAMT | E10: =_xlfn.TEXTAFTER(B10,":") -> 00000002586
A11: "TNFAMN": "", | B11: =SUBSTITUTE(SUBSTITUTE(A11,"""",""),",","") -> TNFAMN: | C11: =_xlfn.TEXTBEFORE(B11,":") -> TNFAMN | D11: =SUBSTITUTE(TRIM(C11)," ","") -> TNFAMN | E11: =_xlfn.TEXTAFTER(B11,":")
A12: "TNFCCD": "***************4903", | B12: =SUBSTITUTE(SUBSTITUTE(A12,"""",""),",","") -> TNFCCD: ***************4903 | C12: =_xlfn.TEXTBEFORE(B12,":") -> TNFCCD | D12: =SUBSTITUTE(TRIM(C12)," ","") -> TNFCCD | E12: =_xlfn.TEXTAFTER(B12,":") -> ***************4903
A13: "TNFEXP": "0000", | B13: =SUBSTITUTE(SUBSTITUTE(A13,"""",""),",","") -> TNFEXP: 0000 | C13: =_xlfn.TEXTBEFORE(B13,":") -> TNFEXP | D13: =SUBSTITUTE(TRIM(C13)," ","") -> TNFEXP | E13: =_xlfn.TEXTAFTER(B13,":") -> 0000
A14: "TNFAUT": "066851", | B14: =SUBSTITUTE(SUBSTITUTE(A14,"""",""),",","") -> TNFAUT: 066851 | C14: =_xlfn.TEXTBEFORE(B14,":") -> TNFAUT | D14: =SUBSTITUTE(TRIM(C14)," ","") -> TNFAUT | E14: =_xlfn.TEXTAFTER(B14,":") -> 066851
A15: "TNFRFC": "", | B15: =SUBSTITUTE(SUBSTITUTE(A15,"""",""),",","") -> TNFRFC: | C15: =_xlfn.TEXTBEFORE(B15,":") -> TNFRFC | D15: =SUBSTITUTE(TRIM(C15)," ","") -> TNFRFC | E15: =_xlfn.TEXTAFTER(B15,":")
A16: "TNFRDS": "", | B16: =SUBSTITUTE(SUBSTITUTE(A16,"""",""),",","") -> TNFRDS: | C16: =_xlfn.TEXTBEFORE(B16,":") -> TNFRDS | D16: =SUBSTITUTE(TRIM(C16)," ","") -> TNFRDS | E16: =_xlfn.TEXTAFTER(B16,":")
A17: "TNFMBR": "", | B17: =SUBSTITUTE(SUBSTITUTE(A17,"""",""),",","") -> TNFMBR: | C17: =_xlfn.TEXTBEFORE(B17,":") -> TNFMBR | D17: =SUBSTITUTE(TRIM(C17)," ","") -> TNFMBR | E17: =_xlfn.TEXTAFTER(B17,":")
A18: "TNFSTS": " ", | B18: =SUBSTITUTE(SUBSTITUTE(A18,"""",""),",","") -> TNFSTS: | C18: =_xlfn.TEXTBEFORE(B18,":") -> TNFSTS | D18: =SUBSTITUTE(TRIM(C18)," ","") -> TNFSTS | E18: =_xlfn.TEXTAFTER(B18,":")
A19: "TNFESI": "", | B19: =SUBSTITUTE(SUBSTITUTE(A19,"""",""),",","") -> TNFESI: | C19: =_xlfn.TEXTBEFORE(B19,":") -> TNFESI | D19: =SUBSTITUTE(TRIM(C19)," ","") -> TNFESI | E19: =_xlfn.TEXTAFTER(B19,":") | G19: {=x} -> #NAME?
A20: "TNFZIP": "", | B20: =SUBSTITUTE(SUBSTITUTE(A20,"""",""),",","") -> TNFZIP: | C20: =_xlfn.TEXTBEFORE(B20,":") -> TNFZIP | D20: =SUBSTITUTE(TRIM(C20)," ","") -> TNFZIP | E20: =_xlfn.TEXTAFTER(B20,":")
A21: "TNFMSR": "S", | B21: =SUBSTITUTE(SUBSTITUTE(A21,"""",""),",","") -> TNFMSR: S | C21: =_xlfn.TEXTBEFORE(B21,":") -> TNFMSR | D21: =SUBSTITUTE(TRIM(C21)," ","") -> TNFMSR | E21: =_xlfn.TEXTAFTER(B21,":") -> S
A22: "TNFEML": "", | B22: =SUBSTITUTE(SUBSTITUTE(A22,"""",""),",","") -> TNFEML: | C22: =_xlfn.TEXTBEFORE(B22,":") -> TNFEML | D22: =SUBSTITUTE(TRIM(C22)," ","") -> TNFEML | E22: =_xlfn.TEXTAFTER(B22,":")
A23: "TNFHSH": "", | B23: =SUBSTITUTE(SUBSTITUTE(A23,"""",""),",","") -> TNFHSH: | C23: =_xlfn.TEXTBEFORE(B23,":") -> TNFHSH | D23: =SUBSTITUTE(TRIM(C23)," ","") -> TNFHSH | E23: =_xlfn.TEXTAFTER(B23,":")
A24: "TNFPLC": 55010, | B24: =SUBSTITUTE(SUBSTITUTE(A24,"""",""),",","") -> TNFPLC: 55010 | C24: =_xlfn.TEXTBEFORE(B24,":") -> TNFPLC | D24: =SUBSTITUTE(TRIM(C24)," ","") -> TNFPLC | E24: =_xlfn.TEXTAFTER(B24,":") -> 55010
A25: "TNFPCN": 1, | B25: =SUBSTITUTE(SUBSTITUTE(A25,"""",""),",","") -> TNFPCN: 1 | C25: =_xlfn.TEXTBEFORE(B25,":") -> TNFPCN | D25: =SUBSTITUTE(TRIM(C25)," ","") -> TNFPCN | E25: =_xlfn.TEXTAFTER(B25,":") -> 1
A26: "TNFPDT": 260123, | B26: =SUBSTITUTE(SUBSTITUTE(A26,"""",""),",","") -> TNFPDT: 260123 | C26: =_xlfn.TEXTBEFORE(B26,":") -> TNFPDT | D26: =SUBSTITUTE(TRIM(C26)," ","") -> TNFPDT | E26: =_xlfn.TEXTAFTER(B26,":") -> 260123
A27: "TNFCCN": 1, | B27: =SUBSTITUTE(SUBSTITUTE(A27,"""",""),",","") -> TNFCCN: 1 | C27: =_xlfn.TEXTBEFORE(B27,":") -> TNFCCN | D27: =SUBSTITUTE(TRIM(C27)," ","") -> TNFCCN | E27: =_xlfn.TEXTAFTER(B27,":") -> 1
A28: "TNFCDT": 260123, | B28: =SUBSTITUTE(SUBSTITUTE(A28,"""",""),",","") -> TNFCDT: 260123 | C28: =_xlfn.TEXTBEFORE(B28,":") -> TNFCDT | D28: =SUBSTITUTE(TRIM(C28)," ","") -> TNFCDT | E28: =_xlfn.TEXTAFTER(B28,":") -> 260123
A29: "TNFCTM": 154417, | B29: =SUBSTITUTE(SUBSTITUTE(A29,"""",""),",","") -> TNFCTM: 154417 | C29: =_xlfn.TEXTBEFORE(B29,":") -> TNFCTM | D29: =SUBSTITUTE(TRIM(C29)," ","") -> TNFCTM | E29: =_xlfn.TEXTAFTER(B29,":") -> 154417
A30: "ATFSST": 0, | B30: =SUBSTITUTE(SUBSTITUTE(A30,"""",""),",","") -> ATFSST: 0 | C30: =_xlfn.TEXTBEFORE(B30,":") -> ATFSST | D30: =SUBSTITUTE(TRIM(C30)," ","") -> ATFSST | E30: =_xlfn.TEXTAFTER(B30,":") -> 0
A31: "ATFIST": 0, | B31: =SUBSTITUTE(SUBSTITUTE(A31,"""",""),",","") -> ATFIST: 0 | C31: =_xlfn.TEXTBEFORE(B31,":") -> ATFIST | D31: =SUBSTITUTE(TRIM(C31)," ","") -> ATFIST | E31: =_xlfn.TEXTAFTER(B31,":") -> 0
... A35: "ATFPRO": "" | B35: =SUBSTITUTE(SUBSTITUTE(A35,"""",""),",","") -> ATFPRO: | C35: =_xlfn.TEXTBEFORE(B35,":") -> ATFPRO | D35: =SUBSTITUTE(TRIM(C35)," ","") -> ATFPRO | E35: =_xlfn.TEXTAFTER(B35,":")

Sheet Sheet1
A2: "SLFTTP": "01", | B2: =TRIM( SUBSTITUTE( SUBSTITUTE( LEFT(A2, FIND(":", A2) - 1), """", "" ), ",", "" ) ) -> SLFTTP | C2: =TRIM( SUBSTITUTE( SUBSTITUTE( _xlfn.TEXTAFTER(A2, ":"), """", "" ), ",", "" ) ) -> 01 | D2: =B2 -> SLFTTP | E2: =C2 -> 01 | H2: "SLFTTP": "01", | I2: =TRIM( SUBSTITUTE( SUBSTITUTE( LEFT(H2, FIND(":", H2) - 1), """", "" ), ",", "" ) ) -> SLFTTP | J2: =TRIM( SUBSTITUTE( SUBSTITUTE( _xlfn.TEXTAFTER(H2, ":"), """", "" ), ",", "" ) ) -> 01 | K2: =I2 -> SLFTTP | L2: =J2 -> 01
A3: "SLFLNT": "01", | B3: =TRIM( SUBSTITUTE( SUBSTITUTE( LEFT(A3, FIND(":", A3) - 1), """", "" ), ",", "" ) ) -> SLFLNT | C3: =TRIM( SUBSTITUTE( SUBSTITUTE( _xlfn.TEXTAFTER(A3, ":"), """", "" ), ",", "" ) ) -> 01 | D3: =B3 -> SLFLNT | E3: =C3 -> 01 | H3: "SLFLNT": "01", | I3: =TRIM( SUBSTITUTE( SUBSTITUTE( LEFT(H3, FIND(":", H3) - 1), """", "" ), ",", "" ) ) -> SLFLNT | J3: =TRIM( SUBSTITUTE( SUBSTITUTE( _xlfn.TEXTAFTER(H3, ":"), """", "" ), ",", "" ) ) -> 01 | K3: =I3 -> SLFLNT | L3: =J3 -> 01
A4: "SLFTDT": "260123", | B4: =TRIM( SUBSTITUTE( SUBSTITUTE( LEFT(A4, FIND(":", A4) - 1), """", "" ), ",", "" ) ) -> SLFTDT | C4: =TRIM( SUBSTITUTE( SUBSTITUTE( _xlfn.TEXTAFTER(A4, ":"), """", "" ), ",", "" ) ) -> 260123 | D4: =B4 -> SLFTDT | E4: =C4 -> 260123 | H4: "SLFTDT": "260123", | I4: =TRIM( SUBSTITUTE( SUBSTITUTE( LEFT(H4, FIND(":", H4) - 1), """", "" ), ",", "" ) ) -> SLFTDT | J4: =TRIM( SUBSTITUTE( SUBSTITUTE( _xlfn.TEXTAFTER(H4, ":"), """", "" ), ",", "" ) ) -> 260123 | K4: =I4 -> SLFTDT | L4: =J4 -> 260123
A5: "SLFTTM": "154417", | B5: =TRIM( SUBSTITUTE( SUBSTITUTE( LEFT(A5, FIND(":", A5) - 1), """", "" ), ",", "" ) ) -> SLFTTM | C5: =TRIM( SUBSTITUTE( SUBSTITUTE( _xlfn.TEXTAFTER(A5, ":"), """", "" ), ",", "" ) ) -> 154417 | D5: =B5 -> SLFTTM | E5: =C5 -> 154417 | H5: "SLFTTM": "154417", | I5: =TRIM( SUBSTITUTE( SUBSTITUTE( LEFT(H5, FIND(":", H5) - 1), """", "" ), ",", "" ) ) -> SLFTTM | J5: =TRIM( SUBSTITUTE( SUBSTITUTE( _xlfn.TEXTAFTER(H5, ":"), """", "" ), ",", "" ) ) -> 154417 | K5: =I5 -> SLFTTM | L5: =J5 -> 154417
A6: "SLFCLK": "00085", | B6: =TRIM( SUBSTITUTE( SUBSTITUTE( LEFT(A6, FIND(":", A6) - 1), """", "" ), ",", "" ) ) -> SLFCLK | C6: =TRIM( SUBSTITUTE( SUBSTITUTE( _xlfn.TEXTAFTER(A6, ":"), """", "" ), ",", "" ) ) -> 00085 | D6: =B6 -> SLFCLK | E6: =C6 -> 00085 | H6: "SLFCLK": "00085", | I6: =TRIM( SUBSTITUTE( SUBSTITUTE( LEFT(H6, FIND(":", H6) - 1), """", "" ), ",", "" ) ) -> SLFCLK | J6: =TRIM( SUBSTITUTE( SUBSTITUTE( _xlfn.TEXTAFTER(H6, ":"), """", "" ), ",", "" ) ) -> 00085 | K6: =I6 -> SLFCLK | L6: =J6 -> 00085
A7: "SLFREG": "085", | B7: =TRIM( SUBSTITUTE( SUBSTITUTE( LEFT(A7, FIND(":", A7) - 1), """", "" ), ",", "" ) ) -> SLFREG | C7: =TRIM( SUBSTITUTE( SUBSTITUTE( _xlfn.TEXTAFTER(A7, ":"), """", "" ), ",", "" ) ) -> 085 | D7: =B7 -> SLFREG | E7: =C7 -> 085 | H7: "SLFREG": "085", | I7: =TRIM( SUBSTITUTE( SUBSTITUTE( LEFT(H7, FIND(":", H7) - 1), """", "" ), ",", "" ) ) -> SLFREG | J7: =TRIM( SUBSTITUTE( SUBSTITUTE( _xlfn.TEXTAFTER(H7, ":"), """", "" ), ",", "" ) ) -> 085 | K7: =I7 -> SLFREG | L7: =J7 -> 085
A8: "SLFTTX": "00531", | B8: =TRIM( SUBSTITUTE( SUBSTITUTE( LEFT(A8, FIND(":", A8) - 1), """", "" ), ",", "" ) ) -> SLFTTX | C8: =TRIM( SUBSTITUTE( SUBSTITUTE( _xlfn.TEXTAFTER(A8, ":"), """", "" ), ",", "" ) ) -> 00531 | D8: =B8 -> SLFTTX | E8: =C8 -> 00531 | H8: "SLFTTX": "00531", | I8: =TRIM( SUBSTITUTE( SUBSTITUTE( LEFT(H8, FIND(":", H8) - 1), """", "" ), ",", "" ) ) -> SLFTTX | J8: =TRIM( SUBSTITUTE( SUBSTITUTE( _xlfn.TEXTAFTER(H8, ":"), """", "" ), ",", "" ) ) -> 00531 | K8: =I8 -> SLFTTX | L8: =J8 -> 00531
A9: "SLFTSQ": "00001", | B9: =TRIM( SUBSTITUTE( SUBSTITUTE( LEFT(A9, FIND(":", A9) - 1), """", "" ), ",", "" ) ) -> SLFTSQ | C9: =TRIM( SUBSTITUTE( SUBSTITUTE( _xlfn.TEXTAFTER(A9, ":"), """", "" ), ",", "" ) ) -> 00001 | D9: =B9 -> SLFTSQ | E9: =C9 -> 00001 | H9: "SLFTSQ": "00002", | I9: =TRIM( SUBSTITUTE( SUBSTITUTE( LEFT(H9, FIND(":", H9) - 1), """", "" ), ",", "" ) ) -> SLFTSQ | J9: =TRIM( SUBSTITUTE( SUBSTITUTE( _xlfn.TEXTAFTER(H9, ":"), """", "" ), ",", "" ) ) -> 00002 | K9: =I9 -> SLFTSQ | L9: =J9 -> 00002
A10: "SLFSKU": "000334898", | B10: =TRIM( SUBSTITUTE( SUBSTITUTE( LEFT(A10, FIND(":", A10) - 1), """", "" ), ",", "" ) ) -> SLFSKU | C10: =TRIM( SUBSTITUTE( SUBSTITUTE( _xlfn.TEXTAFTER(A10, ":"), """", "" ), ",", "" ) ) -> 000334898 | D10: =B10 -> SLFSKU | E10: =C10 -> 000334898 | H10: "SLFSKU": "000169577", | I10: =TRIM( SUBSTITUTE( SUBSTITUTE( LEFT(H10, FIND(":", H10) - 1), """", "" ), ",", "" ) ) -> SLFSKU | J10: =TRIM( SUBSTITUTE( SUBSTITUTE( _xlfn.TEXTAFTER(H10, ":"), """", "" ), ",", "" ) ) -> 000169577 | K10: =I10 -> SLFSKU | L10: =J10 -> 000169577
A11: "SLFQTY": "000000100", | B11: =TRIM( SUBSTITUTE( SUBSTITUTE( LEFT(A11, FIND(":", A11) - 1), """", "" ), ",", "" ) ) -> SLFQTY | C11: =TRIM( SUBSTITUTE( SUBSTITUTE( _xlfn.TEXTAFTER(A11, ":"), """", "" ), ",", "" ) ) -> 000000100 | D11: =B11 -> SLFQTY | E11: =C11 -> 000000100 | H11: "SLFQTY": "000000100", | I11: =TRIM( SUBSTITUTE( SUBSTITUTE( LEFT(H11, FIND(":", H11) - 1), """", "" ), ",", "" ) ) -> SLFQTY | J11: =TRIM( SUBSTITUTE( SUBSTITUTE( _xlfn.TEXTAFTER(H11, ":"), """", "" ), ",", "" ) ) -> 000000100 | K11: =I11 -> SLFQTY | L11: =J11 -> 000000100
A12: "SLFQTN": "", | B12: =TRIM( SUBSTITUTE( SUBSTITUTE( LEFT(A12, FIND(":", A12) - 1), """", "" ), ",", "" ) ) -> SLFQTN | C12: =TRIM( SUBSTITUTE( SUBSTITUTE( _xlfn.TEXTAFTER(A12, ":"), """", "" ), ",", "" ) ) | D12: =B12 -> SLFQTN | E12: =C12 | H12: "SLFQTN": "", | I12: =TRIM( SUBSTITUTE( SUBSTITUTE( LEFT(H12, FIND(":", H12) - 1), """", "" ), ",", "" ) ) -> SLFQTN | J12: =TRIM( SUBSTITUTE( SUBSTITUTE( _xlfn.TEXTAFTER(H12, ":"), """", "" ), ",", "" ) ) | K12: =I12 -> SLFQTN | L12: =J12
A13: "SLFORG": "000001129", | B13: =TRIM( SUBSTITUTE( SUBSTITUTE( LEFT(A13, FIND(":", A13) - 1), """", "" ), ",", "" ) ) -> SLFORG | C13: =TRIM( SUBSTITUTE( SUBSTITUTE( _xlfn.TEXTAFTER(A13, ":"), """", "" ), ",", "" ) ) -> 000001129 | D13: =B13 -> SLFORG | E13: =C13 -> 000001129 | H13: "SLFORG": "000001159", | I13: =TRIM( SUBSTITUTE( SUBSTITUTE( LEFT(H13, FIND(":", H13) - 1), """", "" ), ",", "" ) ) -> SLFORG | J13: =TRIM( SUBSTITUTE( SUBSTITUTE( _xlfn.TEXTAFTER(H13, ":"), """", "" ), ",", "" ) ) -> 000001159 | K13: =I13 -> SLFORG | L13: =J13 -> 000001159
... A71: "SLFECN": 0 | B71: =TRIM( SUBSTITUTE( SUBSTITUTE( LEFT(A71, FIND(":", A71) - 1), """", "" ), ",", "" ) ) -> SLFECN | C71: =TRIM( SUBSTITUTE( SUBSTITUTE( _xlfn.TEXTAFTER(A71, ":"), """", "" ), ",", "" ) ) -> 0 | D71: =B71 -> SLFECN | E71: =C71 -> 0 | H71: "SLFECN": 0 | I71: =TRIM( SUBSTITUTE( SUBSTITUTE( LEFT(H71, FIND(":", H71) - 1), """", "" ), ",", "" ) ) -> SLFECN | J71: =TRIM( SUBSTITUTE( SUBSTITUTE( _xlfn.TEXTAFTER(H71, ":"), """", "" ), ",", "" ) ) -> 0 | K71: =I71 -> SLFECN | L71: =J71 -> 0

Sheet Sheet2
A1: SKU 1 | G1: SKU 2 | M1: SKU 3 | S1: SKU 4 | Y1: Tax 1 | AE1: Tender1
A3: "SLFTTP": "01", | B3: =TRIM( SUBSTITUTE( SUBSTITUTE( LEFT(A3, FIND(":", A3) - 1), """", "" ), ",", "" ) ) -> SLFTTP | C3: =TRIM( SUBSTITUTE( SUBSTITUTE( _xlfn.TEXTAFTER(A3, ":"), """", "" ), ",", "" ) ) -> 01 | D3: =B3 -> SLFTTP | E3: =C3 -> 01 | G3: SLFTTP: "01", | H3: =TRIM( SUBSTITUTE( SUBSTITUTE( LEFT(G3, FIND(":", G3) - 1), """", "" ), ",", "" ) ) -> SLFTTP | I3: =TRIM( SUBSTITUTE( SUBSTITUTE( _xlfn.TEXTAFTER(G3, ":"), """", "" ), ",", "" ) ) -> 01 | J3: =H3 -> SLFTTP | K3: =I3 -> 01 | M3: SLFTTP: "01", | N3: =TRIM( SUBSTITUTE( SUBSTITUTE( LEFT(M3, FIND(":", M3) - 1), """", "" ), ",", "" ) ) -> SLFTTP | O3: =TRIM( SUBSTITUTE( SUBSTITUTE( _xlfn.TEXTAFTER(M3, ":"), """", "" ), ",", "" ) ) -> 01 | P3: =N3 -> SLFTTP | Q3: =O3 -> 01 | S3: SLFTTP: "01", | T3: =TRIM( SUBSTITUTE( SUBSTITUTE( LEFT(S3, FIND(":", S3) - 1), """", "" ), ",", "" ) ) -> SLFTTP | U3: =TRIM( SUBSTITUTE( SUBSTITUTE( _xlfn.TEXTAFTER(S3, ":"), """", "" ), ",", "" ) ) -> 01 | V3: =T3 -> SLFTTP | W3: =U3 -> 01 | Y3: SLFTTP: "01", | Z3: =TRIM( SUBSTITUTE( SUBSTITUTE( LEFT(Y3, FIND(":", Y3) - 1), """", "" ), ",", "" ) ) -> SLFTTP | AA3: =TRIM( SUBSTITUTE( SUBSTITUTE( _xlfn.TEXTAFTER(Y3, ":"), """", "" ), ",", "" ) ) -> 01 | AB3: =Z3 -> SLFTTP | AC3: =AA3 -> 01 | AE3: TNFTTP: "01", | AF3: =TRIM( SUBSTITUTE( SUBSTITUTE( LEFT(AE3, FIND(":", AE3) - 1), """", "" ), ",", "" ) ) -> TNFTTP | AG3: =TRIM( SUBSTITUTE( SUBSTITUTE( _xlfn.TEXTAFTER(AE3, ":"), """", "" ), ",", "" ) ) -> 01 | AH3: =AF3 -> TNFTTP | AI3: =AG3 -> 01
A4: "SLFLNT": "01", | B4: =TRIM( SUBSTITUTE( SUBSTITUTE( LEFT(A4, FIND(":", A4) - 1), """", "" ), ",", "" ) ) -> SLFLNT | C4: =TRIM( SUBSTITUTE( SUBSTITUTE( _xlfn.TEXTAFTER(A4, ":"), """", "" ), ",", "" ) ) -> 01 | D4: =B4 -> SLFLNT | E4: =C4 -> 01 | G4: "SLFLNT": "01", | H4: =TRIM( SUBSTITUTE( SUBSTITUTE( LEFT(G4, FIND(":", G4) - 1), """", "" ), ",", "" ) ) -> SLFLNT | I4: =TRIM( SUBSTITUTE( SUBSTITUTE( _xlfn.TEXTAFTER(G4, ":"), """", "" ), ",", "" ) ) -> 01 | J4: =H4 -> SLFLNT | K4: =I4 -> 01 | M4: "SLFLNT": "01", | N4: =TRIM( SUBSTITUTE( SUBSTITUTE( LEFT(M4, FIND(":", M4) - 1), """", "" ), ",", "" ) ) -> SLFLNT | O4: =TRIM( SUBSTITUTE( SUBSTITUTE( _xlfn.TEXTAFTER(M4, ":"), """", "" ), ",", "" ) ) -> 01 | P4: =N4 -> SLFLNT | Q4: =O4 -> 01 | S4: "SLFLNT": "01", | T4: =TRIM( SUBSTITUTE( SUBSTITUTE( LEFT(S4, FIND(":", S4) - 1), """", "" ), ",", "" ) ) -> SLFLNT | U4: =TRIM( SUBSTITUTE( SUBSTITUTE( _xlfn.TEXTAFTER(S4, ":"), """", "" ), ",", "" ) ) -> 01 | V4: =T4 -> SLFLNT | W4: =U4 -> 01 | Y4: "SLFLNT": "XH", | Z4: =TRIM( SUBSTITUTE( SUBSTITUTE( LEFT(Y4, FIND(":", Y4) - 1), """", "" ), ",", "" ) ) -> SLFLNT | AA4: =TRIM( SUBSTITUTE( SUBSTITUTE( _xlfn.TEXTAFTER(Y4, ":"), """", "" ), ",", "" ) ) -> XH | AB4: =Z4 -> SLFLNT | AC4: =AA4 -> XH | AE4: "TNFTDT": "260126", | AF4: =TRIM( SUBSTITUTE( SUBSTITUTE( LEFT(AE4, FIND(":", AE4) - 1), """", "" ), ",", "" ) ) -> TNFTDT | AG4: =TRIM( SUBSTITUTE( SUBSTITUTE( _xlfn.TEXTAFTER(AE4, ":"), """", "" ), ",", "" ) ) -> 260126 | AH4: =AF4 -> TNFTDT | AI4: =AG4 -> 260126
A5: "SLFTDT": "260126", | B5: =TRIM( SUBSTITUTE( SUBSTITUTE( LEFT(A5, FIND(":", A5) - 1), """", "" ), ",", "" ) ) -> SLFTDT | C5: =TRIM( SUBSTITUTE( SUBSTITUTE( _xlfn.TEXTAFTER(A5, ":"), """", "" ), ",", "" ) ) -> 260126 | D5: =B5 -> SLFTDT | E5: =C5 -> 260126 | G5: "SLFTDT": "260126", | H5: =TRIM( SUBSTITUTE( SUBSTITUTE( LEFT(G5, FIND(":", G5) - 1), """", "" ), ",", "" ) ) -> SLFTDT | I5: =TRIM( SUBSTITUTE( SUBSTITUTE( _xlfn.TEXTAFTER(G5, ":"), """", "" ), ",", "" ) ) -> 260126 | J5: =H5 -> SLFTDT | K5: =I5 -> 260126 | M5: "SLFTDT": "260126", | N5: =TRIM( SUBSTITUTE( SUBSTITUTE( LEFT(M5, FIND(":", M5) - 1), """", "" ), ",", "" ) ) -> SLFTDT | O5: =TRIM( SUBSTITUTE( SUBSTITUTE( _xlfn.TEXTAFTER(M5, ":"), """", "" ), ",", "" ) ) -> 260126 | P5: =N5 -> SLFTDT | Q5: =O5 -> 260126 | S5: "SLFTDT": "260126", | T5: =TRIM( SUBSTITUTE( SUBSTITUTE( LEFT(S5, FIND(":", S5) - 1), """", "" ), ",", "" ) ) -> SLFTDT | U5: =TRIM( SUBSTITUTE( SUBSTITUTE( _xlfn.TEXTAFTER(S5, ":"), """", "" ), ",", "" ) ) -> 260126 | V5: =T5 -> SLFTDT | W5: =U5 -> 260126 | Y5: "SLFTDT": "260126", | Z5: =TRIM( SUBSTITUTE( SUBSTITUTE( LEFT(Y5, FIND(":", Y5) - 1), """", "" ), ",", "" ) ) -> SLFTDT | AA5: =TRIM( SUBSTITUTE( SUBSTITUTE( _xlfn.TEXTAFTER(Y5, ":"), """", "" ), ",", "" ) ) -> 260126 | AB5: =Z5 -> SLFTDT | AC5: =AA5 -> 260126 | AE5: "TNFTTM": "163959", | AF5: =TRIM( SUBSTITUTE( SUBSTITUTE( LEFT(AE5, FIND(":", AE5) - 1), """", "" ), ",", "" ) ) -> TNFTTM | AG5: =TRIM( SUBSTITUTE( SUBSTITUTE( _xlfn.TEXTAFTER(AE5, ":"), """", "" ), ",", "" ) ) -> 163959 | AH5: =AF5 -> TNFTTM | AI5: =AG5 -> 163959
A6: "SLFTTM": "163959", | B6: =TRIM( SUBSTITUTE( SUBSTITUTE( LEFT(A6, FIND(":", A6) - 1), """", "" ), ",", "" ) ) -> SLFTTM | C6: =TRIM( SUBSTITUTE( SUBSTITUTE( _xlfn.TEXTAFTER(A6, ":"), """", "" ), ",", "" ) ) -> 163959 | D6: =B6 -> SLFTTM | E6: =C6 -> 163959 | G6: "SLFTTM": "163959", | H6: =TRIM( SUBSTITUTE( SUBSTITUTE( LEFT(G6, FIND(":", G6) - 1), """", "" ), ",", "" ) ) -> SLFTTM | I6: =TRIM( SUBSTITUTE( SUBSTITUTE( _xlfn.TEXTAFTER(G6, ":"), """", "" ), ",", "" ) ) -> 163959 | J6: =H6 -> SLFTTM | K6: =I6 -> 163959 | M6: "SLFTTM": "163959", | N6: =TRIM( SUBSTITUTE( SUBSTITUTE( LEFT(M6, FIND(":", M6) - 1), """", "" ), ",", "" ) ) -> SLFTTM | O6: =TRIM( SUBSTITUTE( SUBSTITUTE( _xlfn.TEXTAFTER(M6, ":"), """", "" ), ",", "" ) ) -> 163959 | P6: =N6 -> SLFTTM | Q6: =O6 -> 163959 | S6: "SLFTTM": "163959", | T6: =TRIM( SUBSTITUTE( SUBSTITUTE( LEFT(S6, FIND(":", S6) - 1), """", "" ), ",", "" ) ) -> SLFTTM | U6: =TRIM( SUBSTITUTE( SUBSTITUTE( _xlfn.TEXTAFTER(S6, ":"), """", "" ), ",", "" ) ) -> 163959 | V6: =T6 -> SLFTTM | W6: =U6 -> 163959 | Y6: "SLFTTM": "163959", | Z6: =TRIM( SUBSTITUTE( SUBSTITUTE( LEFT(Y6, FIND(":", Y6) - 1), """", "" ), ",", "" ) ) -> SLFTTM | AA6: =TRIM( SUBSTITUTE( SUBSTITUTE( _xlfn.TEXTAFTER(Y6, ":"), """", "" ), ",", "" ) ) -> 163959 | AB6: =Z6 -> SLFTTM | AC6: =AA6 -> 163959 | AE6: "TNFCLK": "00006", | AF6: =TRIM( SUBSTITUTE( SUBSTITUTE( LEFT(AE6, FIND(":", AE6) - 1), """", "" ), ",", "" ) ) -> TNFCLK | AG6: =TRIM( SUBSTITUTE( SUBSTITUTE( _xlfn.TEXTAFTER(AE6, ":"), """", "" ), ",", "" ) ) -> 00006 | AH6: =AF6 -> TNFCLK | AI6: =AG6 -> 00006
A7: "SLFCLK": "00006", | B7: =TRIM( SUBSTITUTE( SUBSTITUTE( LEFT(A7, FIND(":", A7) - 1), """", "" ), ",", "" ) ) -> SLFCLK | C7: =TRIM( SUBSTITUTE( SUBSTITUTE( _xlfn.TEXTAFTER(A7, ":"), """", "" ), ",", "" ) ) -> 00006 | D7: =B7 -> SLFCLK | E7: =C7 -> 00006 | G7: "SLFCLK": "00006", | H7: =TRIM( SUBSTITUTE( SUBSTITUTE( LEFT(G7, FIND(":", G7) - 1), """", "" ), ",", "" ) ) -> SLFCLK | I7: =TRIM( SUBSTITUTE( SUBSTITUTE( _xlfn.TEXTAFTER(G7, ":"), """", "" ), ",", "" ) ) -> 00006 | J7: =H7 -> SLFCLK | K7: =I7 -> 00006 | M7: "SLFCLK": "00006", | N7: =TRIM( SUBSTITUTE( SUBSTITUTE( LEFT(M7, FIND(":", M7) - 1), """", "" ), ",", "" ) ) -> SLFCLK | O7: =TRIM( SUBSTITUTE( SUBSTITUTE( _xlfn.TEXTAFTER(M7, ":"), """", "" ), ",", "" ) ) -> 00006 | P7: =N7 -> SLFCLK | Q7: =O7 -> 00006 | S7: "SLFCLK": "00006", | T7: =TRIM( SUBSTITUTE( SUBSTITUTE( LEFT(S7, FIND(":", S7) - 1), """", "" ), ",", "" ) ) -> SLFCLK | U7: =TRIM( SUBSTITUTE( SUBSTITUTE( _xlfn.TEXTAFTER(S7, ":"), """", "" ), ",", "" ) ) -> 00006 | V7: =T7 -> SLFCLK | W7: =U7 -> 00006 | Y7: "SLFCLK": "00006", | Z7: =TRIM( SUBSTITUTE( SUBSTITUTE( LEFT(Y7, FIND(":", Y7) - 1), """", "" ), ",", "" ) ) -> SLFCLK | AA7: =TRIM( SUBSTITUTE( SUBSTITUTE( _xlfn.TEXTAFTER(Y7, ":"), """", "" ), ",", "" ) ) -> 00006 | AB7: =Z7 -> SLFCLK | AC7: =AA7 -> 00006 | AE7: "TNFREG": "006", | AF7: =TRIM( SUBSTITUTE( SUBSTITUTE( LEFT(AE7, FIND(":", AE7) - 1), """", "" ), ",", "" ) ) -> TNFREG | AG7: =TRIM( SUBSTITUTE( SUBSTITUTE( _xlfn.TEXTAFTER(AE7, ":"), """", "" ), ",", "" ) ) -> 006 | AH7: =AF7 -> TNFREG | AI7: =AG7 -> 006
A8: "SLFREG": "006", | B8: =TRIM( SUBSTITUTE( SUBSTITUTE( LEFT(A8, FIND(":", A8) - 1), """", "" ), ",", "" ) ) -> SLFREG | C8: =TRIM( SUBSTITUTE( SUBSTITUTE( _xlfn.TEXTAFTER(A8, ":"), """", "" ), ",", "" ) ) -> 006 | D8: =B8 -> SLFREG | E8: =C8 -> 006 | G8: "SLFREG": "006", | H8: =TRIM( SUBSTITUTE( SUBSTITUTE( LEFT(G8, FIND(":", G8) - 1), """", "" ), ",", "" ) ) -> SLFREG | I8: =TRIM( SUBSTITUTE( SUBSTITUTE( _xlfn.TEXTAFTER(G8, ":"), """", "" ), ",", "" ) ) -> 006 | J8: =H8 -> SLFREG | K8: =I8 -> 006 | M8: "SLFREG": "006", | N8: =TRIM( SUBSTITUTE( SUBSTITUTE( LEFT(M8, FIND(":", M8) - 1), """", "" ), ",", "" ) ) -> SLFREG | O8: =TRIM( SUBSTITUTE( SUBSTITUTE( _xlfn.TEXTAFTER(M8, ":"), """", "" ), ",", "" ) ) -> 006 | P8: =N8 -> SLFREG | Q8: =O8 -> 006 | S8: "SLFREG": "006", | T8: =TRIM( SUBSTITUTE( SUBSTITUTE( LEFT(S8, FIND(":", S8) - 1), """", "" ), ",", "" ) ) -> SLFREG | U8: =TRIM( SUBSTITUTE( SUBSTITUTE( _xlfn.TEXTAFTER(S8, ":"), """", "" ), ",", "" ) ) -> 006 | V8: =T8 -> SLFREG | W8: =U8 -> 006 | Y8: "SLFREG": "006", | Z8: =TRIM( SUBSTITUTE( SUBSTITUTE( LEFT(Y8, FIND(":", Y8) - 1), """", "" ), ",", "" ) ) -> SLFREG | AA8: =TRIM( SUBSTITUTE( SUBSTITUTE( _xlfn.TEXTAFTER(Y8, ":"), """", "" ), ",", "" ) ) -> 006 | AB8: =Z8 -> SLFREG | AC8: =AA8 -> 006 | AE8: "TNFTTX": "00539", | AF8: =TRIM( SUBSTITUTE( SUBSTITUTE( LEFT(AE8, FIND(":", AE8) - 1), """", "" ), ",", "" ) ) -> TNFTTX | AG8: =TRIM( SUBSTITUTE( SUBSTITUTE( _xlfn.TEXTAFTER(AE8, ":"), """", "" ), ",", "" ) ) -> 00539 | AH8: =AF8 -> TNFTTX | AI8: =AG8 -> 00539
A9: "SLFTTX": "00539", | B9: =TRIM( SUBSTITUTE( SUBSTITUTE( LEFT(A9, FIND(":", A9) - 1), """", "" ), ",", "" ) ) -> SLFTTX | C9: =TRIM( SUBSTITUTE( SUBSTITUTE( _xlfn.TEXTAFTER(A9, ":"), """", "" ), ",", "" ) ) -> 00539 | D9: =B9 -> SLFTTX | E9: =C9 -> 00539 | G9: "SLFTTX": "00539", | H9: =TRIM( SUBSTITUTE( SUBSTITUTE( LEFT(G9, FIND(":", G9) - 1), """", "" ), ",", "" ) ) -> SLFTTX | I9: =TRIM( SUBSTITUTE( SUBSTITUTE( _xlfn.TEXTAFTER(G9, ":"), """", "" ), ",", "" ) ) -> 00539 | J9: =H9 -> SLFTTX | K9: =I9 -> 00539 | M9: "SLFTTX": "00539", | N9: =TRIM( SUBSTITUTE( SUBSTITUTE( LEFT(M9, FIND(":", M9) - 1), """", "" ), ",", "" ) ) -> SLFTTX | O9: =TRIM( SUBSTITUTE( SUBSTITUTE( _xlfn.TEXTAFTER(M9, ":"), """", "" ), ",", "" ) ) -> 00539 | P9: =N9 -> SLFTTX | Q9: =O9 -> 00539 | S9: "SLFTTX": "00539", | T9: =TRIM( SUBSTITUTE( SUBSTITUTE( LEFT(S9, FIND(":", S9) - 1), """", "" ), ",", "" ) ) -> SLFTTX | U9: =TRIM( SUBSTITUTE( SUBSTITUTE( _xlfn.TEXTAFTER(S9, ":"), """", "" ), ",", "" ) ) -> 00539 | V9: =T9 -> SLFTTX | W9: =U9 -> 00539 | Y9: "SLFTTX": "00539", | Z9: =TRIM( SUBSTITUTE( SUBSTITUTE( LEFT(Y9, FIND(":", Y9) - 1), """", "" ), ",", "" ) ) -> SLFTTX | AA9: =TRIM( SUBSTITUTE( SUBSTITUTE( _xlfn.TEXTAFTER(Y9, ":"), """", "" ), ",", "" ) ) -> 00539 | AB9: =Z9 -> SLFTTX | AC9: =AA9 -> 00539 | AE9: "TNFTSQ": "00006", | AF9: =TRIM( SUBSTITUTE( SUBSTITUTE( LEFT(AE9, FIND(":", AE9) - 1), """", "" ), ",", "" ) ) -> TNFTSQ | AG9: =TRIM( SUBSTITUTE( SUBSTITUTE( _xlfn.TEXTAFTER(AE9, ":"), """", "" ), ",", "" ) ) -> 00006 | AH9: =AF9 -> TNFTSQ | AI9: =AG9 -> 00006
A10: "SLFTSQ": "00001", | B10: =TRIM( SUBSTITUTE( SUBSTITUTE( LEFT(A10, FIND(":", A10) - 1), """", "" ), ",", "" ) ) -> SLFTSQ | C10: =TRIM( SUBSTITUTE( SUBSTITUTE( _xlfn.TEXTAFTER(A10, ":"), """", "" ), ",", "" ) ) -> 00001 | D10: =B10 -> SLFTSQ | E10: =C10 -> 00001 | G10: "SLFTSQ": "00002", | H10: =TRIM( SUBSTITUTE( SUBSTITUTE( LEFT(G10, FIND(":", G10) - 1), """", "" ), ",", "" ) ) -> SLFTSQ | I10: =TRIM( SUBSTITUTE( SUBSTITUTE( _xlfn.TEXTAFTER(G10, ":"), """", "" ), ",", "" ) ) -> 00002 | J10: =H10 -> SLFTSQ | K10: =I10 -> 00002 | M10: "SLFTSQ": "00003", | N10: =TRIM( SUBSTITUTE( SUBSTITUTE( LEFT(M10, FIND(":", M10) - 1), """", "" ), ",", "" ) ) -> SLFTSQ | O10: =TRIM( SUBSTITUTE( SUBSTITUTE( _xlfn.TEXTAFTER(M10, ":"), """", "" ), ",", "" ) ) -> 00003 | P10: =N10 -> SLFTSQ | Q10: =O10 -> 00003 | S10: "SLFTSQ": "00004", | T10: =TRIM( SUBSTITUTE( SUBSTITUTE( LEFT(S10, FIND(":", S10) - 1), """", "" ), ",", "" ) ) -> SLFTSQ | U10: =TRIM( SUBSTITUTE( SUBSTITUTE( _xlfn.TEXTAFTER(S10, ":"), """", "" ), ",", "" ) ) -> 00004 | V10: =T10 -> SLFTSQ | W10: =U10 -> 00004 | Y10: "SLFTSQ": "00005", | Z10: =TRIM( SUBSTITUTE( SUBSTITUTE( LEFT(Y10, FIND(":", Y10) - 1), """", "" ), ",", "" ) ) -> SLFTSQ | AA10: =TRIM( SUBSTITUTE( SUBSTITUTE( _xlfn.TEXTAFTER(Y10, ":"), """", "" ), ",", "" ) ) -> 00005 | AB10: =Z10 -> SLFTSQ | AC10: =AA10 -> 00005 | AE10: "TNFFCD": "DC", | AF10: =TRIM( SUBSTITUTE( SUBSTITUTE( LEFT(AE10, FIND(":", AE10) - 1), """", "" ), ",", "" ) ) -> TNFFCD | AG10: =TRIM( SUBSTITUTE( SUBSTITUTE( _xlfn.TEXTAFTER(AE10, ":"), """", "" ), ",", "" ) ) -> DC | AH10: =AF10 -> TNFFCD | AI10: =AG10 -> DC
A11: "SLFSKU": "000301286", | B11: =TRIM( SUBSTITUTE( SUBSTITUTE( LEFT(A11, FIND(":", A11) - 1), """", "" ), ",", "" ) ) -> SLFSKU | C11: =TRIM( SUBSTITUTE( SUBSTITUTE( _xlfn.TEXTAFTER(A11, ":"), """", "" ), ",", "" ) ) -> 000301286 | D11: =B11 -> SLFSKU | E11: =C11 -> 000301286 | G11: "SLFSKU": "000334898", | H11: =TRIM( SUBSTITUTE( SUBSTITUTE( LEFT(G11, FIND(":", G11) - 1), """", "" ), ",", "" ) ) -> SLFSKU | I11: =TRIM( SUBSTITUTE( SUBSTITUTE( _xlfn.TEXTAFTER(G11, ":"), """", "" ), ",", "" ) ) -> 000334898 | J11: =H11 -> SLFSKU | K11: =I11 -> 000334898 | M11: "SLFSKU": "000050481", | N11: =TRIM( SUBSTITUTE( SUBSTITUTE( LEFT(M11, FIND(":", M11) - 1), """", "" ), ",", "" ) ) -> SLFSKU | O11: =TRIM( SUBSTITUTE( SUBSTITUTE( _xlfn.TEXTAFTER(M11, ":"), """", "" ), ",", "" ) ) -> 000050481 | P11: =N11 -> SLFSKU | Q11: =O11 -> 000050481 | S11: "SLFSKU": "000491309", | T11: =TRIM( SUBSTITUTE( SUBSTITUTE( LEFT(S11, FIND(":", S11) - 1), """", "" ), ",", "" ) ) -> SLFSKU | U11: =TRIM( SUBSTITUTE( SUBSTITUTE( _xlfn.TEXTAFTER(S11, ":"), """", "" ), ",", "" ) ) -> 000491309 | V11: =T11 -> SLFSKU | W11: =U11 -> 000491309 | Y11: "SLFSKU": "000000000", | Z11: =TRIM( SUBSTITUTE( SUBSTITUTE( LEFT(Y11, FIND(":", Y11) - 1), """", "" ), ",", "" ) ) -> SLFSKU | AA11: =TRIM( SUBSTITUTE( SUBSTITUTE( _xlfn.TEXTAFTER(Y11, ":"), """", "" ), ",", "" ) ) -> 000000000 | AB11: =Z11 -> SLFSKU | AC11: =AA11 -> 000000000 | AE11: "TNFAMT": "00000002912", | AF11: =TRIM( SUBSTITUTE( SUBSTITUTE( LEFT(AE11, FIND(":", AE11) - 1), """", "" ), ",", "" ) ) -> TNFAMT | AG11: =TRIM( SUBSTITUTE( SUBSTITUTE( _xlfn.TEXTAFTER(AE11, ":"), """", "" ), ",", "" ) ) -> 00000002912 | AH11: =AF11 -> TNFAMT | AI11: =AG11 -> 00000002912
A12: "SLFQTY": "000000100", | B12: =TRIM( SUBSTITUTE( SUBSTITUTE( LEFT(A12, FIND(":", A12) - 1), """", "" ), ",", "" ) ) -> SLFQTY | C12: =TRIM( SUBSTITUTE( SUBSTITUTE( _xlfn.TEXTAFTER(A12, ":"), """", "" ), ",", "" ) ) -> 000000100 | D12: =B12 -> SLFQTY | E12: =C12 -> 000000100 | G12: "SLFQTY": "000000100", | H12: =TRIM( SUBSTITUTE( SUBSTITUTE( LEFT(G12, FIND(":", G12) - 1), """", "" ), ",", "" ) ) -> SLFQTY | I12: =TRIM( SUBSTITUTE( SUBSTITUTE( _xlfn.TEXTAFTER(G12, ":"), """", "" ), ",", "" ) ) -> 000000100 | J12: =H12 -> SLFQTY | K12: =I12 -> 000000100 | M12: "SLFQTY": "000000100", | N12: =TRIM( SUBSTITUTE( SUBSTITUTE( LEFT(M12, FIND(":", M12) - 1), """", "" ), ",", "" ) ) -> SLFQTY | O12: =TRIM( SUBSTITUTE( SUBSTITUTE( _xlfn.TEXTAFTER(M12, ":"), """", "" ), ",", "" ) ) -> 000000100 | P12: =N12 -> SLFQTY | Q12: =O12 -> 000000100 | S12: "SLFQTY": "000000100", | T12: =TRIM( SUBSTITUTE( SUBSTITUTE( LEFT(S12, FIND(":", S12) - 1), """", "" ), ",", "" ) ) -> SLFQTY | U12: =TRIM( SUBSTITUTE( SUBSTITUTE( _xlfn.TEXTAFTER(S12, ":"), """", "" ), ",", "" ) ) -> 000000100 | V12: =T12 -> SLFQTY | W12: =U12 -> 000000100 | Y12: "SLFQTY": "000000100", | Z12: =TRIM( SUBSTITUTE( SUBSTITUTE( LEFT(Y12, FIND(":", Y12) - 1), """", "" ), ",", "" ) ) -> SLFQTY | AA12: =TRIM( SUBSTITUTE( SUBSTITUTE( _xlfn.TEXTAFTER(Y12, ":"), """", "" ), ",", "" ) ) -> 000000100 | AB12: =Z12 -> SLFQTY | AC12: =AA12 -> 000000100 | AE12: "TNFAMN": "", | AF12: =TRIM( SUBSTITUTE( SUBSTITUTE( LEFT(AE12, FIND(":", AE12) - 1), """", "" ), ",", "" ) ) -> TNFAMN | AG12: =TRIM( SUBSTITUTE( SUBSTITUTE( _xlfn.TEXTAFTER(AE12, ":"), """", "" ), ",", "" ) ) | AH12: =AF12 -> TNFAMN | AI12: =AG12
A13: "SLFQTN": "", | B13: =TRIM( SUBSTITUTE( SUBSTITUTE( LEFT(A13, FIND(":", A13) - 1), """", "" ), ",", "" ) ) -> SLFQTN | C13: =TRIM( SUBSTITUTE( SUBSTITUTE( _xlfn.TEXTAFTER(A13, ":"), """", "" ), ",", "" ) ) | D13: =B13 -> SLFQTN | E13: =C13 | G13: "SLFQTN": "", | H13: =TRIM( SUBSTITUTE( SUBSTITUTE( LEFT(G13, FIND(":", G13) - 1), """", "" ), ",", "" ) ) -> SLFQTN | I13: =TRIM( SUBSTITUTE( SUBSTITUTE( _xlfn.TEXTAFTER(G13, ":"), """", "" ), ",", "" ) ) | J13: =H13 -> SLFQTN | K13: =I13 | M13: "SLFQTN": "", | N13: =TRIM( SUBSTITUTE( SUBSTITUTE( LEFT(M13, FIND(":", M13) - 1), """", "" ), ",", "" ) ) -> SLFQTN | O13: =TRIM( SUBSTITUTE( SUBSTITUTE( _xlfn.TEXTAFTER(M13, ":"), """", "" ), ",", "" ) ) | P13: =N13 -> SLFQTN | Q13: =O13 | S13: "SLFQTN": "", | T13: =TRIM( SUBSTITUTE( SUBSTITUTE( LEFT(S13, FIND(":", S13) - 1), """", "" ), ",", "" ) ) -> SLFQTN | U13: =TRIM( SUBSTITUTE( SUBSTITUTE( _xlfn.TEXTAFTER(S13, ":"), """", "" ), ",", "" ) ) | V13: =T13 -> SLFQTN | W13: =U13 | Y13: "SLFQTN": "", | Z13: =TRIM( SUBSTITUTE( SUBSTITUTE( LEFT(Y13, FIND(":", Y13) - 1), """", "" ), ",", "" ) ) -> SLFQTN | AA13: =TRIM( SUBSTITUTE( SUBSTITUTE( _xlfn.TEXTAFTER(Y13, ":"), """", "" ), ",", "" ) ) | AB13: =Z13 -> SLFQTN | AC13: =AA13 | AE13: "TNFCCD": "***************8644", | AF13: =TRIM( SUBSTITUTE( SUBSTITUTE( LEFT(AE13, FIND(":", AE13) - 1), """", "" ), ",", "" ) ) -> TNFCCD | AG13: =TRIM( SUBSTITUTE( SUBSTITUTE( _xlfn.TEXTAFTER(AE13, ":"), """", "" ), ",", "" ) ) -> ***************8644 | AH13: =AF13 -> TNFCCD | AI13: =AG13 -> ***************8644
